Workbook

Sheet DATA-INFO
A1: Start Data | B1: End Data | C1: SIT/UAT/REGRESI
A2: 1 | B2: 1 | C2: REGRESI

Sheet Datatable
A1: NO | B1: ACTION | C1: SCENARIO | D1: URL | E1: USERNAME | F1: PASSWORD | G1: URL 2 | H1: STATUS | I1: KETERANGAN
A2: 1 | B2: LIMIT 1 | C2: Claim Benefit Pusat Limit 1 | D2: https://btn-uat.harpa-go.com:9443/login | E2: NIKI.NAKILA@TEST.COM | F2: Btnbest123#

Sheet dt_Initial Data Entry
A1: NO | B1: KODE PROGRAM
A2: 1 | B2: Regular
A3: 2

Sheet LIMIT 1
A1: TestCase | B1: IsRunning | C1: Keyword | D1: ObjectName | E1: Value | F1: Application
A2: Login | B2: Yes | F2: BTNBEST
C3: start_chrome_driver
C4: go_to_url | E4: =Datatable!$D$1 -> URL
C5: screenshot_full_whole
C6: set_text | D6: txtUsername | E6: =Datatable!$E$1 -> USERNAME
C7: set_text | D7: txtPassword | E7: =Datatable!$F$1 -> PASSWORD
C8: screenshot_full_whole
C9: click | D9: btnShowPassword
C10: screenshot_full_whole
C11: click | D11: btnLogin
C12: wait_until_element_exist | D12: btnAvatarLogin
C13: screenshot_full_whole
A14: Pengajuan Claim Benefit | B14: Yes | F14: BTNBEST
C15: click | D15: btnBurgerIcon
C16: click | D16: btnClaimBenefit
C17: wait_until_element_exist | D17: btnCreateNewBenefit
C18: screenshot_full_whole
C19: click | D19: btnCreateNewBenefit
C20: wait_until_element_exist | D20: btnSave
C21: screenshot_full_whole
C22: click | D22: btnSearchCategory
C23: wait_until_element_exist | D23: txtSearchCategory
C24: set_text | D24: txtSearchCategory | E24: ='Data LIMIT 1'!$B$1 -> CATEGORY
C25: send_key | D25: txtSearchCategory | E25: ENTER
C26: screenshot
C27: click_replace | D27: btnRplOption | E27: ='Data LIMIT 1'!$B$1 -> CATEGORY
C28: click | D28: btnSearchType
C29: wait_until_element_exist | D29: txtSearchType
C30: set_text | D30: txtSearchType | E30: ='Data LIMIT 1'!$C$1 -> TYPE
C31: send_key | D31: txtSearchType | E31: ENTER
C32: screenshot
C33: click_replace | D33: btnRplOption | E33: ='Data LIMIT 1'!$C$1 -> TYPE
C34: set_text | D34: txtPurpose | E34: ='Data LIMIT 1'!$D$1 -> PURPOSE
C35: click | D35: btnSelectClaimCurrency
C36: click_replace | D36: btnOptionSelectDiv | E36: ='Data LIMIT 1'!$E$1 -> CLAIM CURRENCY
C37: set_text | D37: txtReference | E37: ='Data LIMIT 1'!$F$1 -> REFERENCE
C38: set_text | D38: txtDescription | E38: ='Data LIMIT 1'!$G$1 -> DESCRIPTION
C39: screenshot_full_whole
C40: click | D40: btnSave
...

Sheet Data LIMIT 1
A1: NO | B1: CATEGORY | C1: TYPE | D1: PURPOSE | E1: CLAIM CURRENCY | F1: REFERENCE | G1: DESCRIPTION | H1: FROM DATE CLAIM | I1: TO DATE CLAIM | J1: CLAIM ITEM | K1: JUMLAH UNIT | L1: AMOUNT/UNIT | M1: ADJUSTED CLAIM | N1: PROVIDER | O1: DESCRIPTION | P1: RELATIONSHIP | Q1: NAMA RELATIONSHIP | R1: BILL NUMBER | S1: DIAGNOSA | T1: RS / KLINIK | U1: RS / KLINIK NAME
A2: 1 | B2: Claim Medical | C2: Reimburse | D2: reimburse | E2: IDR | G2: Reimburse Duitku | H2: 02-Feb-2026 | I2: 03-Feb-2026 | J2: Gigi | K2: 1 | L2: 1000000 | O2: Claim Gigi | P2: Pegawai | Q2: NIKI NAKILA H | R2: 111111111 | S2: Gigi Berlobang | T2: Anna Pekayon

Sheet Xpath
A1: ObjectName | B1: XPATH
